Workbook

Sheet Pivot
A3: Row Labels | B3: Count of Kind
B4: 316
A5: BID | B5: 437
A6: BID+DEAL+NEXT | B6: 1
A7: BID+NEXT | B7: 124
A8: BID+NEXT+ROTATE | B8: 75
A9: NEXT | B9: 220
A10: Grand Total | B10: 1173

Sheet BakerBridge
A1: Subfolder | B1: Filename | C1: DealNumber | D1: B1 | E1: Kind | F1: North | G1: East | H1: South | I1: West | J1: B2 | K1: Hands | L1: B2 | M1: BC Import | R1: Dealer | S1: Auction | T1: Contract | U1: Declarer | V1: Lead | W1: Analysis
A2: ='CSV Import'!A2 -> 100Deals | B2: ='CSV Import'!B2 -> deal001.html | C2: ='CSV Import'!C2 -> 1 | E2: =IF('CSV Import'!D2="","",'CSV Import'!D2) -> BID+NEXT | F2: =IF('CSV Import'!E2="","",'CSV Import'!E2) -> S:J86 H:A98 D:8653 C:AKQ | G2: =IF('CSV Import'!F2="","",'CSV Import'!F2) -> S:A9 H:QT54 D:QJT2 C:JT3 | H2: =IF('CSV Import'!G2="","",'CSV Import'!G2) -> S:Q53 H:762 D:AK4 C:8742 | I2: =IF('CSV Import'!H2="","",'CSV Import'!H2) -> S:KT742 H:KJ3 D:97 C:965 | K2: =4-COUNTIF(F2:I2,"") -> 4 | M2: =SUBSTITUTE(SUBSTITUTE(SUBSTITUTE(SUBSTITUTE(F2,"S:","")," H:",".")," D:",".")," C:",".") -> J86.A98.8653.AKQ | N2: =SUBSTITUTE(SUBSTITUTE(SUBSTITUTE(SUBSTITUTE(G2,"S:","")," H:",".")," D:",".")," C:",".") -> A9.QT54.QJT2.JT3 | O2: =SUBSTITUTE(SUBSTITUTE(SUBSTITUTE(SUBSTITUTE(H2,"S:","")," H:",".")," D:",".")," C:",".") -> Q53.762.AK4.8742 | P2: =SUBSTITUTE(SUBSTITUTE(SUBSTITUTE(SUBSTITUTE(I2,"S:","")," H:",".")," D:",".")," C:",".") -> KT742.KJ3.97.965 | R2: =IF('CSV Import'!I2="","",'CSV Import'!I2) -> North | S2: =IF('CSV Import'!J2="","",'CSV Import'!J2) -> 1D pass 1NT | pass pass pass | T2: =IF('CSV Import'!K2="","",'CSV Import'!K2) -> 1NT | U2: =IF('CSV Import'!L2="","",'CSV Import'!L2) -> South | V2: =IF('CSV Import'!M2="","",'CSV Import'!M2) -> S4 | W2: =IF('CSV Import'!N2="","",'CSV Import'!N2) -> You are South and it is your bid. Decide what you would say, then click on BID. [BID 1NT]\nDo not be tempted to say 2!D, even with such good 3-card help. To support partner's minor suit opening you should have at least 4 cards in the suit. Remember he may have opened a 3-card suit.\nInstead you bid 1NT showing a balanced 6-10 point hand with no 4-card Major suit. Partner passes.\nSouth plays 1NT. West leads the !S4. East wins the !SA, then plays the !S9. West takes his !SK and leads another !S, East discarding a !H.\nMake a Plan, then click NEXT. [NEXT]\nTo make a PLAN for a Notrump contract you should count your winners.\nWinners: !S 1 : !H 1 : !D 2 : !C 3 : Total = 7\nFor this deal you see that you already have all the winners you need to make the contract. So you just want to be sure you don't do something stupid that would jeopardize those winners.\nYou win the !SQ, then lead to the !CA, !CK, !CQ. Everybody follows suit to these three tricks. Next you take the !HA. Then you play a small !D to your !DK, then play your !DA. You have now won your required 7 tricks, but you have a bonus. Since all the !Cs except the !C8 have been played your !C8 is now high and you make an overtrick.\nClick NEXT to see the complete deal. [NEXT]\nBut even with this type of hand you should make sure you take them in the right order. Here, if you had played the !DA and !DK BEFORE you played the !C A K Q you would have had no entry back to the fourth !C in your hand. In this case it was only an overtrick, in other deals it could make the difference between making and going down.
A3: ='CSV Import'!A3 -> 100Deals | B3: ='CSV Import'!B3 -> deal002.html | C3: ='CSV Import'!C3 -> 2 | E3: =IF('CSV Import'!D3="","",'CSV Import'!D3) -> BID+NEXT | F3: =IF('CSV Import'!E3="","",'CSV Import'!E3) -> S:74 H:KQJ3 D:AK75 C:863 | G3: =IF('CSV Import'!F3="","",'CSV Import'!F3) -> S:J986 H:A5 D:Q32 C:QJT4 | H3: =IF('CSV Import'!G3="","",'CSV Import'!G3) -> S:AKQ3 H:T982 D:J4 C:K72 | I3: =IF('CSV Import'!H3="","",'CSV Import'!H3) -> S:T52 H:764 D:T986 C:A95 | K3: =4-COUNTIF(F3:I3,"") -> 4 | M3: =SUBSTITUTE(SUBSTITUTE(SUBSTITUTE(SUBSTITUTE(F3,"S:","")," H:",".")," D:",".")," C:",".") -> 74.KQJ3.AK75.863 | N3: =SUBSTITUTE(SUBSTITUTE(SUBSTITUTE(SUBSTITUTE(G3,"S:","")," H:",".")," D:",".")," C:",".") -> J986.A5.Q32.QJT4 | O3: =SUBSTITUTE(SUBSTITUTE(SUBSTITUTE(SUBSTITUTE(H3,"S:","")," H:",".")," D:",".")," C:",".") -> AKQ3.T982.J4.K72 | P3: =SUBSTITUTE(SUBSTITUTE(SUBSTITUTE(SUBSTITUTE(I3,"S:","")," H:",".")," D:",".")," C:",".") -> T52.764.T986.A95 | R3: =IF('CSV Import'!I3="","",'CSV Import'!I3) -> North | S3: =IF('CSV Import'!J3="","",'CSV Import'!J3) -> 1D pass 1H | pass 2H pass 4H | pass pass pass | T3: =IF('CSV Import'!K3="","",'CSV Import'!K3) -> 4H | U3: =IF('CSV Import'!L3="","",'CSV Import'!L3) -> South | V3: =IF('CSV Import'!M3="","",'CSV Import'!M3) -> DT | W3: =IF('CSV Import'!N3="","",'CSV Import'!N3) -> You are South and it is your bid. Decide what you would say, then click on BID. [BID 1!H]\nA jump to 2NT would be descriptive, but your first goal is to seek a Major suit fit. When you have two 4-card Majors you should respond "up-the-line" so you bid 1!H. Partner says 2!H. What do you bid now? [BID 4!H]\nPartner would not support your !H suit without 4 cards so you have an 8-card Major fit. There is no point in bidding !Ss.\nPartner has at least 13 points and you have 13 so you bid the game.\nSouth plays 4!H. West leads the !DT.\nMake a Plan, then click NEXT. [NEXT]\nTo make a PLAN for a suit contract you should count your losers.\nLosers: !S 0 : !H 1 : !D 0 : !C 3 : Total = 4\nThere is nothing you can do about losing the Ace of trumps. The three !C losers would only happen if West has the !CA and East wins a trick early, (say with the !HA), and leads a !C through your !CK.\nYou can take care of this possibility by discarding a !C from dummy BEFORE you play trumps. So win the !DK, and play !SA, !SK, !SQ, discarding dummy's !C3 on the last one. Then pull trumps. You will end up losing two !Cs and the !HA.\nClick NEXT to see the Deal that could have set you. [NEXT]\nEast would win his !HA and would switch to a black suit to lead up to dummy's weakness. In this case he would surely lead the !CQ, and you would lose three !C tricks and be down before you started.\nMaking a PLAN is a necessary part of being a good Declarer and Visualizing what might happen is a necessary part of making a Plan.
A4: ='CSV Import'!A4 -> 100Deals | B4: ='CSV Import'!B4 -> deal003.html | C4: ='CSV Import'!C4 -> 3 | E4: =IF('CSV Import'!D4="","",'CSV Import'!D4) -> BID+NEXT | F4: =IF('CSV Import'!E4="","",'CSV Import'!E4) -> S:AQ5 H:74 D:Q962 C:AJT8 | G4: =IF('CSV Import'!F4="","",'CSV Import'!F4) -> S:KT H:QJT982 D:83 C:652 | H4: =IF('CSV Import'!G4="","",'CSV Import'!G4) -> S:872 H:K6 D:AKJ4 C:KQ74 | I4: =IF('CSV Import'!H4="","",'CSV Import'!H4) -> S:J9643 H:A53 D:T75 C:93 | K4: =4-COUNTIF(F4:I4,"") -> 4 | M4: =SUBSTITUTE(SUBSTITUTE(SUBSTITUTE(SUBSTITUTE(F4,"S:","")," H:",".")," D:",".")," C:",".") -> AQ5.74.Q962.AJT8 | N4: =SUBSTITUTE(SUBSTITUTE(SUBSTITUTE(SUBSTITUTE(G4,"S:","")," H:",".")," D:",".")," C:",".") -> KT.QJT982.83.652 | O4: =SUBSTITUTE(SUBSTITUTE(SUBSTITUTE(SUBSTITUTE(H4,"S:","")," H:",".")," D:",".")," C:",".") -> 872.K6.AKJ4.KQ74 | P4: =SUBSTITUTE(SUBSTITUTE(SUBSTITUTE(SUBSTITUTE(I4,"S:","")," H:",".")," D:",".")," C:",".") -> J9643.A53.T75.93 | R4: =IF('CSV Import'!I4="","",'CSV Import'!I4) -> East | S4: =IF('CSV Import'!J4="","",'CSV Import'!J4) -> pass 1NT | pass 3NT pass pass | pass | T4: =IF('CSV Import'!K4="","",'CSV Import'!K4) -> 3NT | U4: =IF('CSV Import'!L4="","",'CSV Import'!L4) -> South | V4: =IF('CSV Import'!M4="","",'CSV Import'!M4) -> S4 | W4: =IF('CSV Import'!N4="","",'CSV Import'!N4) -> You are South and it is your bid. Decide what you would say, then click on BID. [BID 1NT]\nWith 16 points and a balanced hand you should open 1NT. Do not worry about the lack of a !S stopper, a 1NT opening does not guarantee stoppers in all four suits.\nPartner raises you to 3NT.\nSouth plays 3NT. West leads the !S4.\nMake a Plan, then click NEXT. [NEXT]\nWinners: !S 1 : !H 0 : !D 4 : !C 4 : Total = 9\nIt's nice to have a hand where the Winner count is 9. And guess what? West probably has the !SK, so you can finesse on the first trick for an overtrick.\nHOLD IT! JUST STEP AWAY FROM THE QUEEN OF SPADES AND NOBODY WILL GET HURT.\nWhat if you tried the finesse and East had the !SK? And what if he then switched to the !HQ? And what if your opponents then took the next 6 !H tricks? \nI think you get the idea. Win the !SA immediately and then take your other 8 tricks.\nClick NEXT to see the complete Deal. [NEXT]\nThis wasn't one of those times.
A5: ='CSV Import'!A5 -> 100Deals | B5: ='CSV Import'!B5 -> deal004.html | C5: ='CSV Import'!C5 -> 4 | E5: =IF('CSV Import'!D5="","",'CSV Import'!D5) -> BID+NEXT | F5: =IF('CSV Import'!E5="","",'CSV Import'!E5) -> S:KQJ H:A862 D:Q63 C:T94 | G5: =IF('CSV Import'!F5="","",'CSV Import'!F5) -> S:72 H:QT43 D:AJ92 C:Q73 | H5: =IF('CSV Import'!G5="","",'CSV Import'!G5) -> S:T98653 H:K7 D:84 C:AKJ | I5: =IF('CSV Import'!H5="","",'CSV Import'!H5) -> S:A4 H:J95 D:KT75 C:8652 | K5: =4-COUNTIF(F5:I5,"") -> 4 | M5: =SUBSTITUTE(SUBSTITUTE(SUBSTITUTE(SUBSTITUTE(F5,"S:","")," H:",".")," D:",".")," C:",".") -> KQJ.A862.Q63.T94 | N5: =SUBSTITUTE(SUBSTITUTE(SUBSTITUTE(SUBSTITUTE(G5,"S:","")," H:",".")," D:",".")," C:",".") -> 72.QT43.AJ92.Q73 | O5: =SUBSTITUTE(SUBSTITUTE(SUBSTITUTE(SUBSTITUTE(H5,"S:","")," H:",".")," D:",".")," C:",".") -> T98653.K7.84.AKJ | P5: =SUBSTITUTE(SUBSTITUTE(SUBSTITUTE(SUBSTITUTE(I5,"S:","")," H:",".")," D:",".")," C:",".") -> A4.J95.KT75.8652 | R5: =IF('CSV Import'!I5="","",'CSV Import'!I5) -> South | S5: =IF('CSV Import'!J5="","",'CSV Import'!J5) -> 1S | pass 2H pass 2S | pass 4S pass pass | pass | T5: =IF('CSV Import'!K5="","",'CSV Import'!K5) -> 4S | U5: =IF('CSV Import'!L5="","",'CSV Import'!L5) -> South | V5: =IF('CSV Import'!M5="","",'CSV Import'!M5) -> D5 | W5: =IF('CSV Import'!N5="","",'CSV Import'!N5) -> You are South and it is your bid. Decide what you would say, then click on BID. [BID 1!S]\nDon't think of passing. With 11 HCP and 2 length points you open 1!S. Partner responds 2!H. What is your next bid? [BID 2!S]\nYou must bid and you want to show that you have a bare minimum. You don't want to say 2NT because of that doubleton nothing !D. So you rebid your 6-card !S suit. Partner bids 4!S and everybody passes.\nSouth plays 4!S. West leads the !D5 on which you play dummy's !D3. East wins !DJ, plays !DA, then !D2.\nMake a Plan, then click NEXT. [NEXT]\nLosers: !S 1 : !H 0 : !D 2 : !C 1 : Total = 4\nYou have already lost the 2 !Ds and you sure can't escape losing the Ace of trumps. So you mustnot lose a !C trick. So your Plan will be to pull trumps, then finesse East for the !CQ. \nYou ruff the third !D, play !Ss until the !SA appears. When you regain the lead you pull any outstanding trumps, play one high !C, (in case someone has a singleton !CQ), then enter dummy with the !HA and make the !C finesse. Half of the time you make the contract, the other half you don't.\nClick NEXT to see the full deal. [NEXT]\nIt's never great when the success of your contract depends on a finesse, but sometimes that's your only hope - a 50% chance.
A6: ='CSV Import'!A6 -> 100Deals | B6: ='CSV Import'!B6 -> deal005.html | C6: ='CSV Import'!C6 -> 5 | E6: =IF('CSV Import'!D6="","",'CSV Import'!D6) -> BID+NEXT | F6: =IF('CSV Import'!E6="","",'CSV Import'!E6) -> S:J64 H:Q7 D:A983 C:KQ76 | G6: =IF('CSV Import'!F6="","",'CSV Import'!F6) -> S:A7 H:K653 D:762 C:T543 | H6: =IF('CSV Import'!G6="","",'CSV Import'!G6) -> S:KQT3 H:A4 D:QJT5 C:AJ2 | I6: =IF('CSV Import'!H6="","",'CSV Import'!H6) -> S:9852 H:JT982 D:K4 C:98 | K6: =4-COUNTIF(F6:I6,"") -> 4 | M6: =SUBSTITUTE(SUBSTITUTE(SUBSTITUTE(SUBSTITUTE(F6,"S:","")," H:",".")," D:",".")," C:",".") -> J64.Q7.A983.KQ76 | N6: =SUBSTITUTE(SUBSTITUTE(SUBSTITUTE(SUBSTITUTE(G6,"S:","")," H:",".")," D:",".")," C:",".") -> A7.K653.762.T543 | O6: =SUBSTITUTE(SUBSTITUTE(SUBSTITUTE(SUBSTITUTE(H6,"S:","")," H:",".")," D:",".")," C:",".") -> KQT3.A4.QJT5.AJ2 | P6: =SUBSTITUTE(SUBSTITUTE(SUBSTITUTE(SUBSTITUTE(I6,"S:","")," H:",".")," D:",".")," C:",".") -> 9852.JT982.K4.98 | R6: =IF('CSV Import'!I6="","",'CSV Import'!I6) -> East | S6: =IF('CSV Import'!J6="","",'CSV Import'!J6) -> pass 1NT | pass 3NT pass pass | pass | T6: =IF('CSV Import'!K6="","",'CSV Import'!K6) -> 3NT | U6: =IF('CSV Import'!L6="","",'CSV Import'!L6) -> South | V6: =IF('CSV Import'!M6="","",'CSV Import'!M6) -> HJ | W6: =IF('CSV Import'!N6="","",'CSV Import'!N6) -> You are South and it is your bid. Decide what you would say, then click on BID. [BID 1NT]\nYou have a very solid 17 points and a balanced hand. You open 1NT. Partner responds 3NT and you pass.\nSouth plays 3NT. West leads the !HJ. You hopefully put on the !HQ, but East plays the !HK.\nMake a Plan, then click NEXT. [NEXT]\nYou hopefully put on the !HQ, but East plays the !HK.\nWinners: !S 0 : !H 1 : !D 1 : !C 4 : Total = 6\nA hold-up won't help unless East had a doubleton !H, giving West a 7-card suit. So you win your !HA. The !S suit is solid after the !SA is played, but before you could enjoy those 3 tricks the defenders would have really enjoyed a bunch of !Hs.\nYour only hope is to win 8 more tricks before you lose the lead. That means the !D finesse had better work. At trick 2 you lead your !DQ, playing low from dummy if West doesn't cover. Repeat the finesse as necessary. When West has the !DK you will make your contract, and when East has the !DK you will go down. That's a 50% chance, just like most finesses. But remember, if you had tried to establish the !S suit instead of taking the finesse your chance of making 3NT would be 0%.\nClick for the full deal. [NEXT]\n
A7: ='CSV Import'!A7 -> 100Deals | B7: ='CSV Import'!B7 -> deal006.html | C7: ='CSV Import'!C7 -> 6 | E7: =IF('CSV Import'!D7="","",'CSV Import'!D7) -> BID+NEXT+ROTATE | F7: =IF('CSV Import'!E7="","",'CSV Import'!E7) -> S:QJT9 H:A5 D:7542 C:973 | G7: =IF('CSV Import'!F7="","",'CSV Import'!F7) -> S:K63 H:QJT83 D:J C:KJ62 | H7: =IF('CSV Import'!G7="","",'CSV Import'!G7) -> S:A2 H:K742 D:A863 C:AT5 | I7: =IF('CSV Import'!H7="","",'CSV Import'!H7) -> S:8754 H:96 D:KQT9 C:Q84 | K7: =4-COUNTIF(F7:I7,"") -> 4 | M7: =SUBSTITUTE(SUBSTITUTE(SUBSTITUTE(SUBSTITUTE(F7,"S:","")," H:",".")," D:",".")," C:",".") -> QJT9.A5.7542.973 | N7: =SUBSTITUTE(SUBSTITUTE(SUBSTITUTE(SUBSTITUTE(G7,"S:","")," H:",".")," D:",".")," C:",".") -> K63.QJT83.J.KJ62 | O7: =SUBSTITUTE(SUBSTITUTE(SUBSTITUTE(SUBSTITUTE(H7,"S:","")," H:",".")," D:",".")," C:",".") -> A2.K742.A863.AT5 | P7: =SUBSTITUTE(SUBSTITUTE(SUBSTITUTE(SUBSTITUTE(I7,"S:","")," H:",".")," D:",".")," C:",".") -> 8754.96.KQT9.Q84 | R7: =IF('CSV Import'!I7="","",'CSV Import'!I7) -> North | S7: =IF('CSV Import'!J7="","",'CSV Import'!J7) -> 1NT | pass pass pass | | T7: =IF('CSV Import'!K7="","",'CSV Import'!K7) -> 1NT | U7: =IF('CSV Import'!L7="","",'CSV Import'!L7) -> North | V7: =IF('CSV Import'!M7="","",'CSV Import'!M7) -> HQ | W7: =IF('CSV Import'!N7="","",'CSV Import'!N7) -> You are South and it is your bid. Decide what you would say, then click on BID. [BID pass]\nYou have 7 points so you know your side does not have a game. You also have no reason to think there is any better contract than 1NT. So you pass.\nNorth would play 1NT. To make life more convenient the hands will be rotated so that South becomes declarer. \nClick ROTATE. [ROTATE]\nSouth plays 1NT. West leads the !HQ.\nMake a Plan, then click NEXT. [NEXT]\nWinners: !S 1 : !H 2 : !D 1 : !C 1 : Total = 5\nYou need two more winners. Even if the !Ds split 3-2 you can get only one more from that suit. So clearly you must use the !S suit. Since you have only one entry to dummy you must save it until the right time.\nWin the first trick with the !HK. Then play !SA followed by !S2. Continue playing !Ss until the !SK is forced out. Win whatever they play next and play your other winners. You cannot be stopped from taking 7 tricks.\nClick NEXT to see the full deal. [NEXT]\nWhat would you try next? A !S finesse? Whether West took his !SK right then or later you would go down. You could never reach dummy again.
A8: ='CSV Import'!A8 -> 100Deals | B8: ='CSV Import'!B8 -> deal007.html | C8: ='CSV Import'!C8 -> 7 | E8: =IF('CSV Import'!D8="","",'CSV Import'!D8) -> BID+NEXT | F8: =IF('CSV Import'!E8="","",'CSV Import'!E8) -> S:T64 H:KJ7 D:86 C:J7532 | G8: =IF('CSV Import'!F8="","",'CSV Import'!F8) -> S:982 H:5 D:QT742 C:AK96 | H8: =IF('CSV Import'!G8="","",'CSV Import'!G8) -> S:QJ5 H:AQT963 D:AK5 C:Q | I8: =IF('CSV Import'!H8="","",'CSV Import'!H8) -> S:AK73 H:842 D:J93 C:T84 | K8: =4-COUNTIF(F8:I8,"") -> 4 | M8: =SUBSTITUTE(SUBSTITUTE(SUBSTITUTE(SUBSTITUTE(F8,"S:","")," H:",".")," D:",".")," C:",".") -> T64.KJ7.86.J7532 | N8: =SUBSTITUTE(SUBSTITUTE(SUBSTITUTE(SUBSTITUTE(G8,"S:","")," H:",".")," D:",".")," C:",".") -> 982.5.QT742.AK96 | O8: =SUBSTITUTE(SUBSTITUTE(SUBSTITUTE(SUBSTITUTE(H8,"S:","")," H:",".")," D:",".")," C:",".") -> QJ5.AQT963.AK5.Q | P8: =SUBSTITUTE(SUBSTITUTE(SUBSTITUTE(SUBSTITUTE(I8,"S:","")," H:",".")," D:",".")," C:",".") -> AK73.842.J93.T84 | R8: =IF('CSV Import'!I8="","",'CSV Import'!I8) -> South | S8: =IF('CSV Import'!J8="","",'CSV Import'!J8) -> 1H | pass 2H pass 4H | pass pass pass | | T8: =IF('CSV Import'!K8="","",'CSV Import'!K8) -> 4H | U8: =IF('CSV Import'!L8="","",'CSV Import'!L8) -> South | V8: =IF('CSV Import'!M8="","",'CSV Import'!M8) -> SA | W8: =IF('CSV Import'!N8="","",'CSV Import'!N8) -> You are South and it is your bid. Decide what you would say, then click on BID. [BID 4!H]\nYou have a nice hand, but 20 points is not strong enough to open 2!C. \nSo you open 1!H. Partner raises to 2!H. What do you bid now? [BID pass]\nPartner's raise to 2!H shows 6-10 points. You figure that should be enough for game but even if he has the full T you are not in slam range. So you bid the game. \nSouth plays 4!H. West leads !SA, then switches to !H2.\nMake a Plan, then click NEXT. [NEXT]\nLosers: !S 2 : !H 0 : !D 1 : !C 1 : Total = 4\nIt's a good thing you stopped at game - partner's hand is about as bad as it could be.\nThe PLAN turns out simple. You can't avoid either of the three black losers so you must eliminate the !D loser. You can ruff it in dummy. Just to be safe you pull one more round of trumps, then play !DA, !DK and !D5, ruffing in dummy. You will eventually get to your hand (with a !S or a !C ruff) and pull the last trump.\nClick NEXT to see the full deal. [NEXT]\nOnly a real beginner would have pulled all the trumps and not been able to ruff that !D.
A9: ='CSV Import'!A9 -> 100Deals | B9: ='CSV Import'!B9 -> deal008.html | C9: ='CSV Import'!C9 -> 8 | E9: =IF('CSV Import'!D9="","",'CSV Import'!D9) -> BID+NEXT+ROTATE | F9: =IF('CSV Import'!E9="","",'CSV Import'!E9) -> S:74 H:K53 D:AK962 C:KQ3 | G9: =IF('CSV Import'!F9="","",'CSV Import'!F9) -> S:QJT82 H:T86 D:754 C:A5 | H9: =IF('CSV Import'!G9="","",'CSV Import'!G9) -> S:A9 H:AJ2 D:QJ3 C:JT862 | I9: =IF('CSV Import'!H9="","",'CSV Import'!H9) -> S:K653 H:Q974 D:T8 C:974 | K9: =4-COUNTIF(F9:I9,"") -> 4 | M9: =SUBSTITUTE(SUBSTITUTE(SUBSTITUTE(SUBSTITUTE(F9,"S:","")," H:",".")," D:",".")," C:",".") -> 74.K53.AK962.KQ3 | N9: =SUBSTITUTE(SUBSTITUTE(SUBSTITUTE(SUBSTITUTE(G9,"S:","")," H:",".")," D:",".")," C:",".") -> QJT82.T86.754.A5 | O9: =SUBSTITUTE(SUBSTITUTE(SUBSTITUTE(SUBSTITUTE(H9,"S:","")," H:",".")," D:",".")," C:",".") -> A9.AJ2.QJ3.JT862 | P9: =SUBSTITUTE(SUBSTITUTE(SUBSTITUTE(SUBSTITUTE(I9,"S:","")," H:",".")," D:",".")," C:",".") -> K653.Q974.T8.974 | R9: =IF('CSV Import'!I9="","",'CSV Import'!I9) -> West | S9: =IF('CSV Import'!J9="","",'CSV Import'!J9) -> pass 1C | pass 1D pass 1NT | pass 3NT pass pass | pass | T9: =IF('CSV Import'!K9="","",'CSV Import'!K9) -> 3NT | U9: =IF('CSV Import'!L9="","",'CSV Import'!L9) -> North | V9: =IF('CSV Import'!M9="","",'CSV Import'!M9) -> SQ | W9: =IF('CSV Import'!N9="","",'CSV Import'!N9) -> You are South and it is your bid. Decide what you would say, then click on BID. [BID pass]\nWith 16 points as Responder you are not quite strong enough for a jump-shift to 2 !D. That requires at least 17 points. A jump to 3NT fits the point range (16-18) but promises a stopper in all unbid suits. So instead you bid 1!D, knowing partner is forced to keep the bidding alive. He now replies 1NT. What is your next bid? [BID pass]\nUntil now you were thinking the hand might end up in a slam. Now, with partner's minimum rebid, you happily say 3NT which partner passes.\nNorth would play 3NT. \nClick [ROTATE]\nSouth plays 3NT. West leads the !SQ. East puts on the !SK.\nMake a Plan, then click NEXT. [NEXT]\nWinners: !S 1 : !H 2 : !D 5 : !C 0 : Total = 8\nLet's say you hold up on the first !S, hoping they switch suits. HA! They aren't about to switch suits and they drive out your !SA at trick 2. That actually clears the situation up and makes this plan pretty simple to make.\nYou have taken 1 !S, and you will surely make 5 !Ds. Despite the solidity of those !Cs you dare not try to win a !C trick, because the defenders will pounce on that first !C and then win a bunch of !S tricks. \nSo that makes it clear that you need 3 !H tricks, and there's only one way to get them. After taking your five !D tricks, play a !H to the !HK, then a !H back, finessing the !HJ. Half of the time you will make this contract, the other half of the time they will bury you with !Ss.\nClick NEXT to see the full deal. [NEXT]\n
A10: ='CSV Import'!A10 -> 100Deals | B10: ='CSV Import'!B10 -> deal009.html | C10: ='CSV Import'!C10 -> 9 | E10: =IF('CSV Import'!D10="","",'CSV Import'!D10) -> BID+NEXT+ROTATE | F10: =IF('CSV Import'!E10="","",'CSV Import'!E10) -> S:952 H:KQ92 D:KQ83 C:J7 | G10: =IF('CSV Import'!F10="","",'CSV Import'!F10) -> S:KQJ8 H: D:9764 C:QT652 | H10: =IF('CSV Import'!G10="","",'CSV Import'!G10) -> S:T63 H:AT754 D:AJ2 C:AK | I10: =IF('CSV Import'!H10="","",'CSV Import'!H10) -> S:A74 H:J863 D:T5 C:9843 | K10: =4-COUNTIF(F10:I10,"") -> 4 | M10: =SUBSTITUTE(SUBSTITUTE(SUBSTITUTE(SUBSTITUTE(F10,"S:","")," H:",".")," D:",".")," C:",".") -> 952.KQ92.KQ83.J7 | N10: =SUBSTITUTE(SUBSTITUTE(SUBSTITUTE(SUBSTITUTE(G10,"S:","")," H:",".")," D:",".")," C:",".") -> KQJ8..9764.QT652 | O10: =SUBSTITUTE(SUBSTITUTE(SUBSTITUTE(SUBSTITUTE(H10,"S:","")," H:",".")," D:",".")," C:",".") -> T63.AT754.AJ2.AK | P10: =SUBSTITUTE(SUBSTITUTE(SUBSTITUTE(SUBSTITUTE(I10,"S:","")," H:",".")," D:",".")," C:",".") -> A74.J863.T5.9843 | R10: =IF('CSV Import'!I10="","",'CSV Import'!I10) -> North | S10: =IF('CSV Import'!J10="","",'CSV Import'!J10) -> 1H | pass 3H pass 4H | pass pass pass | T10: =IF('CSV Import'!K10="","",'CSV Import'!K10) -> 4H | U10: =IF('CSV Import'!L10="","",'CSV Import'!L10) -> North | V10: =IF('CSV Import'!M10="","",'CSV Import'!M10) | W10: =IF('CSV Import'!N10="","",'CSV Import'!N10) -> You are South and it is your bid. Decide what you would say, then click on BID. [BID 3!H]\nYou have 12 points which isn't quite enough to force to game.\nIt is just right for a limit raise though, so you bid 3!H.\nPartner does bid the game.\nNorth would play 4!H.\nClick [ROTATE]\nSouth plays 4!H. The defense takes the first three !S tricks, then switches to a !C.\nMake a Plan, then click NEXT. [NEXT]\nLosers: !S 3 : !H ?? : !D 0 : !C 0 : Total = 3+??\nWith no more outside losers your task is very very simple:DO NOT LOSE A TRUMP TRICK.\nThere is no problem if trumps split 2-2 or 3-1, so you can put your mind to 4-0 splits only. If West holds !H J 8 6 3 then it won't matter whether your first trump play is !HA or !HK, you will still be able to finesse the !HJ. But if East holds !H J 8 6 3 it is vital that you first play either the !HK or !HQ. If you start with the !HA you will have lost your finesse position. The general rule is to first play a high trump from the hand that has two. That preserves a finesse through either defender's !H J x x x.\nClick NEXT to see the full deal. [NEXT]\nNext visualize the situation if your first play was the !HK. West would show out and you would play the !HQ, then a small !H finessing your !HT. \nFinally visualize the situation if your first play was the !HK and it was East who showed out. You would play a small !H to your !HA, then lead a !H toward dummy finessing with the !H9.\nUsing the correct Plan guarantees the contract however !Hs split.
A11: ='CSV Import'!A11 -> 100Deals | B11: ='CSV Import'!B11 -> deal010.html | C11: ='CSV Import'!C11 -> 10 | E11: =IF('CSV Import'!D11="","",'CSV Import'!D11) -> BID+NEXT | F11: =IF('CSV Import'!E11="","",'CSV Import'!E11) -> S:KQ92 H:952 D:K7 C:KQ83 | G11: =IF('CSV Import'!F11="","",'CSV Import'!F11) -> S: H:A874 D:QJ632 C:T764 | H11: =IF('CSV Import'!G11="","",'CSV Import'!G11) -> S:A8754 H:T63 D:A8 C:AJ2 | I11: =IF('CSV Import'!H11="","",'CSV Import'!H11) -> S:JT63 H:KQJ D:T954 C:95 | K11: =4-COUNTIF(F11:I11,"") -> 4 | M11: =SUBSTITUTE(SUBSTITUTE(SUBSTITUTE(SUBSTITUTE(F11,"S:","")," H:",".")," D:",".")," C:",".") -> KQ92.952.K7.KQ83 | N11: =SUBSTITUTE(SUBSTITUTE(SUBSTITUTE(SUBSTITUTE(G11,"S:","")," H:",".")," D:",".")," C:",".") -> .A874.QJ632.T764 | O11: =SUBSTITUTE(SUBSTITUTE(SUBSTITUTE(SUBSTITUTE(H11,"S:","")," H:",".")," D:",".")," C:",".") -> A8754.T63.A8.AJ2 | P11: =SUBSTITUTE(SUBSTITUTE(SUBSTITUTE(SUBSTITUTE(I11,"S:","")," H:",".")," D:",".")," C:",".") -> JT63.KQJ.T954.95 | R11: =IF('CSV Import'!I11="","",'CSV Import'!I11) -> North | S11: =IF('CSV Import'!J11="","",'CSV Import'!J11) -> 1C pass 1S | pass 2S pass 4S | pass pass pass | T11: =IF('CSV Import'!K11="","",'CSV Import'!K11) -> 4S | U11: =IF('CSV Import'!L11="","",'CSV Import'!L11) -> South | V11: =IF('CSV Import'!M11="","",'CSV Import'!M11) | W11: =IF('CSV Import'!N11="","",'CSV Import'!N11) -> You are South and it is your bid. Decide what you would say, then click on BID. [BID 1!S]\nPartner has opened and you have 14 points. You know you belong in game but there is no need to jump and use up bidding space. You respond 1!S.\nPartner now bids 2!S. What do you bid next? [BID 4!S]\nYou know you should be in game and now you know the suit. You bid 4!S.\nSouth plays 4!S. The defense quickly takes three !H tricks, then switches to a !D.\nMake a Plan, then click NEXT. [NEXT]\nLosers: !S 0? : !H 3 : !D 0 : !C 0 : Total = 3?\nThis Deal is VERY similar to Deal 9 in that you are only worried about a 4-0 trump split. The reason that it shows up right here is to point out the difference between J 8 6 3 and J T 6 3.\nIf East holds !S J T 6 3 then there is nothing you can do about it - you will go down. If you lead a !S from dummy he will "split his honors" by playing the !ST. This will force your !SA and he can just sit back and wait for his !SJ to make a trick.\nBut if it is West with !S J T 6 3 you can keep him from winning a !S trick, IF YOUR FIRST !S PLAY IS THE !SA. East shows out and you play a small !S toward dummy's !S K Q 9. If West plays low you insert the !S9, if he plays one of his honors you win it, then return to your hand and finesse him out of the other honor.\nClick NEXT to see the full deal. [NEXT]\nIf your first !S was !SK or !SQ then it would be too late.\nClick NEXT to see an alternate deal. [NEXT]\nTo summarize: If you are missing J x x x your first play should be from the hand with two honors. Then you will be able to finesse in either direction. If you are missing J T x x your first play should be honor from the hand with only one. This will leave you with a double-finesse position in one direction. If the other defender has the trumps there is nothing you can do.
A12: ='CSV Import'!A12 -> 100Deals | B12: ='CSV Import'!B12 -> deal011.html | C12: ='CSV Import'!C12 -> 11 | E12: =IF('CSV Import'!D12="","",'CSV Import'!D12) -> BID+NEXT | F12: =IF('CSV Import'!E12="","",'CSV Import'!E12) -> S:K82 H:754 D:K9542 C:Q3 | G12: =IF('CSV Import'!F12="","",'CSV Import'!F12) -> S:JT97 H:KQT6 D:J6 C:J54 | H12: =IF('CSV Import'!G12="","",'CSV Import'!G12) -> S:A63 H:A92 D:A87 C:A976 | I12: =IF('CSV Import'!H12="","",'CSV Import'!H12) -> S:Q54 H:J83 D:QT3 C:KT82 | K12: =4-COUNTIF(F12:I12,"") -> 4 | M12: =SUBSTITUTE(SUBSTITUTE(SUBSTITUTE(SUBSTITUTE(F12,"S:","")," H:",".")," D:",".")," C:",".") -> K82.754.K9542.Q3 | N12: =SUBSTITUTE(SUBSTITUTE(SUBSTITUTE(SUBSTITUTE(G12,"S:","")," H:",".")," D:",".")," C:",".") -> JT97.KQT6.J6.J54 | O12: =SUBSTITUTE(SUBSTITUTE(SUBSTITUTE(SUBSTITUTE(H12,"S:","")," H:",".")," D:",".")," C:",".") -> A63.A92.A87.A976 | P12: =SUBSTITUTE(SUBSTITUTE(SUBSTITUTE(SUBSTITUTE(I12,"S:","")," H:",".")," D:",".")," C:",".") -> Q54.J83.QT3.KT82 | R12: =IF('CSV Import'!I12="","",'CSV Import'!I12) -> East | S12: =IF('CSV Import'!J12="","",'CSV Import'!J12) -> pass 1NT | pass 2NT pass 3NT | pass pass pass | | T12: =IF('CSV Import'!K12="","",'CSV Import'!K12) -> 3NT | U12: =IF('CSV Import'!L12="","",'CSV Import'!L12) -> South | V12: =IF('CSV Import'!M12="","",'CSV Import'!M12) -> C2 | W12: =IF('CSV Import'!N12="","",'CSV Import'!N12) -> You are South and it is your bid. Decide what you would say, then click on BID. [BID 1NT]\nAces and Spaces is the description you often hear about this hand. But the REAL description is 16 points, balanced. So you open 1NT. Partner replies 2NT. What do you bid now? [BID 3NT]\nPartner is INVITING you to bid 3NT. If you have 17 points you should bid 3NT. If you have 15 points you should pass.\nWith 16 points you must make a judgement. This one is actually easy, despite the negative sound of "Aces and Spaces". In strength terms Aces are undervalued. Instead of being worth 4 points they are actually worth about 4.3 points. So you really do have a 17 point hand, and you bid 3NT.\nSouth plays 3NT. West leads the !C2.\nMake a Plan, then click NEXT. [NEXT]\nWinner count: !S 2 : !H 1 : !D 2 : !C 1 : Total = 6\nWow. Things do look a little Acey/Spacey. If the !Ds are 3-2, which is likely, you can establish 2 tricks there. You need one more and the best hope is the !CQ. There is a very good chance that West led from the !CK. So with a brief prayer to Brigidda (the Goddess of Bridge) you put up the !CQ. It wins the trick.\nNow you are on cruise-control. Play a !D to the !DA. Play another !D back to dummy's !DK (both defenders follow). Now a third !D sets up the rest of the suit.\nClick NEXT to see the full deal. [NEXT]\n
A13: ='CSV Import'!A13 -> 100Deals | B13: ='CSV Import'!B13 -> deal012.html | C13: ='CSV Import'!C13 -> 12 | E13: =IF('CSV Import'!D13="","",'CSV Import'!D13) -> BID+NEXT+ROTATE | F13: =IF('CSV Import'!E13="","",'CSV Import'!E13) -> S:85 H:J762 D:83 C:AKQ43 | G13: =IF('CSV Import'!F13="","",'CSV Import'!F13) -> S:QT43 H:54 D:JT964 C:95 | H13: =IF('CSV Import'!G13="","",'CSV Import'!G13) -> S:AK72 H:A83 D:AQ72 C:62 | I13: =IF('CSV Import'!H13="","",'CSV Import'!H13) -> S:J96 H:KQT9 D:K5 C:JT87 | K13: =4-COUNTIF(F13:I13,"") -> 4 | M13: =SUBSTITUTE(SUBSTITUTE(SUBSTITUTE(SUBSTITUTE(F13,"S:","")," H:",".")," D:",".")," C:",".") -> 85.J762.83.AKQ43 | N13: =SUBSTITUTE(SUBSTITUTE(SUBSTITUTE(SUBSTITUTE(G13,"S:","")," H:",".")," D:",".")," C:",".") -> QT43.54.JT964.95 | O13: =SUBSTITUTE(SUBSTITUTE(SUBSTITUTE(SUBSTITUTE(H13,"S:","")," H:",".")," D:",".")," C:",".") -> AK72.A83.AQ72.62 | P13: =SUBSTITUTE(SUBSTITUTE(SUBSTITUTE(SUBSTITUTE(I13,"S:","")," H:",".")," D:",".")," C:",".") -> J96.KQT9.K5.JT87 | R13: =IF('CSV Import'!I13="","",'CSV Import'!I13) -> North | S13: =IF('CSV Import'!J13="","",'CSV Import'!J13) -> 1NT | pass 2C pass 2S | pass 3NT pass pass | pass | T13: =IF('CSV Import'!K13="","",'CSV Import'!K13) -> 3NT | U13: =IF('CSV Import'!L13="","",'CSV Import'!L13) -> North | V13: =IF('CSV Import'!M13="","",'CSV Import'!M13) -> DJ | W13: =IF('CSV Import'!N13="","",'CSV Import'!N13) -> You are South and it is your bid. Decide what you would say, then click on BID. [BID 2!C]\nDespite the great !C suit, you have a 4-card Major. It is your duty to first seek an 8-card Major fit, so you bid 2!C (Stayman). Partner replies 2!S. What do you bid? [BID 3NT]\nWell, that wasn't the Major suit you were hoping for.\nBut with 11 points you have enough for game, so you bid 3NT.\nNorth would play 3NT.\nClick [ROTATE]\nSouth plays 3NT. West leads !DJ, East plays !DK.\nMake a Plan, then click NEXT. [NEXT]\nWinners: !S 2 : !H 1 : !D 2 : !C 3 : Total = 8\nThanks to the opening lead you get an extra !D winner. Well, since the finesse would have worked it really isn't extra, it's just nice to know about it early. You need to find one more winner and the !C suit beckons. A 3-3 split would be very nice, but a 4-2 is more likely. Even with a 4-2 split you can still make your fifth !C good - but you must be careful with entries.\nSince you have no immediate problem in any suit you can afford to give up the lead. So you play the !C2 from your hand and the !C3 from dummy. In other words, you duck a !C. Somebody will win this trick cheaply and no doubt play another !D. You don't mind at all - you win the !DQ, the !S A K, the !HA and dummy's !C A K Q 4, all of which are good.\nClick NEXT to see the full deal. [NEXT]\nIf you played a high !C first you would never have an entry back to dummy. You would have been forced to try to get there with the !HJ but as you can see, that wouldn't work.\nIf you had just played the !Cs from the top you would have made an overtrick when they split 3-3, but gone down when they split 4-2. Making an overtrick about 40% of the time is a high price to pay for going down the other 60%.
... A1174: ='CSV Import'!A1174 -> Weak2 | B1174: ='CSV Import'!B1174 -> deal20.html | C1174: ='CSV Import'!C1174 -> 20 | E1174: =IF('CSV Import'!D1174="","",'CSV Import'!D1174) -> BID | F1174: =IF('CSV Import'!E1174="","",'CSV Import'!E1174) -> S:A93 H:QJT754 D:74 C:J2 | G1174: =IF('CSV Import'!F1174="","",'CSV Import'!F1174) -> S:52 H:K962 D:KJ95 C:K64 | H1174: =IF('CSV Import'!G1174="","",'CSV Import'!G1174) -> S:KQJT84 H: D:Q86 C:AQ93 | I1174: =IF('CSV Import'!H1174="","",'CSV Import'!H1174) -> S:76 H:A83 D:AT32 C:T875 | K1174: =4-COUNTIF(F1174:I1174,"") -> 4 | M1174: =SUBSTITUTE(SUBSTITUTE(SUBSTITUTE(SUBSTITUTE(F1174,"S:","")," H:",".")," D:",".")," C:",".") -> A93.QJT754.74.J2 | N1174: =SUBSTITUTE(SUBSTITUTE(SUBSTITUTE(SUBSTITUTE(G1174,"S:","")," H:",".")," D:",".")," C:",".") -> 52.K962.KJ95.K64 | O1174: =SUBSTITUTE(SUBSTITUTE(SUBSTITUTE(SUBSTITUTE(H1174,"S:","")," H:",".")," D:",".")," C:",".") -> KQJT84..Q86.AQ93 | P1174: =SUBSTITUTE(SUBSTITUTE(SUBSTITUTE(SUBSTITUTE(I1174,"S:","")," H:",".")," D:",".")," C:",".") -> 76.A83.AT32.T875 | R1174: =IF('CSV Import'!I1174="","",'CSV Import'!I1174) -> North | S1174: =IF('CSV Import'!J1174="","",'CSV Import'!J1174) -> 2H pass 2S | pass 3S pass 4S | pass pass pass | T1174: =IF('CSV Import'!K1174="","",'CSV Import'!K1174) -> 4S | U1174: =IF('CSV Import'!L1174="","",'CSV Import'!L1174) -> South | V1174: =IF('CSV Import'!M1174="","",'CSV Import'!M1174) | W1174: =IF('CSV Import'!N1174="","",'CSV Import'!N1174) -> The bidding has gone as shown. Decide what you would bid, then click on BID above. [BID 2!S]\n\nYou know have just a 6-card !H fit so you can be no worse off in !Ss. You respond 2!S and partner raises to 3!S. What do you bid now? [BID 4!S]\n\nIt isn't a sure thing, but take a chance. Bid 4!S.

Sheet CSV Import
A1: Subfolder | B1: Filename | C1: DealNumber | D1: Kind | E1: NorthHand | F1: EastHand | G1: SouthHand | H1: WestHand | I1: Dealer | J1: Auction | K1: Contract | L1: Declarer | M1: Lead | N1: Analysis
A2: 100Deals | B2: deal001.html | C2: 1 | D2: BID+NEXT | E2: S:J86 H:A98 D:8653 C:AKQ | F2: S:A9 H:QT54 D:QJT2 C:JT3 | G2: S:Q53 H:762 D:AK4 C:8742 | H2: S:KT742 H:KJ3 D:97 C:965 | I2: North | J2: 1D pass 1NT | pass pass pass | K2: 1NT | L2: South | M2: S4 | N2: You are South and it is your bid. Decide what you would say, then click on BID. [BID 1NT]\nDo not be tempted to say 2!D, even with such good 3-card help. To support partner's minor suit opening you should have at least 4 cards in the suit. Remember he may have opened a 3-card suit.\nInstead you bid 1NT showing a balanced 6-10 point hand with no 4-card Major suit. Partner passes.\nSouth plays 1NT. West leads the !S4. East wins the !SA, then plays the !S9. West takes his !SK and leads another !S, East discarding a !H.\nMake a Plan, then click NEXT. [NEXT]\nTo make a PLAN for a Notrump contract you should count your winners.\nWinners: !S 1 : !H 1 : !D 2 : !C 3 : Total = 7\nFor this deal you see that you already have all the winners you need to make the contract. So you just want to be sure you don't do something stupid that would jeopardize those winners.\nYou win the !SQ, then lead to the !CA, !CK, !CQ. Everybody follows suit to these three tricks. Next you take the !HA. Then you play a small !D to your !DK, then play your !DA. You have now won your required 7 tricks, but you have a bonus. Since all the !Cs except the !C8 have been played your !C8 is now high and you make an overtrick.\nClick NEXT to see the complete deal. [NEXT]\nBut even with this type of hand you should make sure you take them in the right order. Here, if you had played the !DA and !DK BEFORE you played the !C A K Q you would have had no entry back to the fourth !C in your hand. In this case it was only an overtrick, in other deals it could make the difference between making and going down.
A3: 100Deals | B3: deal002.html | C3: 2 | D3: BID+NEXT | E3: S:74 H:KQJ3 D:AK75 C:863 | F3: S:J986 H:A5 D:Q32 C:QJT4 | G3: S:AKQ3 H:T982 D:J4 C:K72 | H3: S:T52 H:764 D:T986 C:A95 | I3: North | J3: 1D pass 1H | pass 2H pass 4H | pass pass pass | K3: 4H | L3: South | M3: DT | N3: You are South and it is your bid. Decide what you would say, then click on BID. [BID 1!H]\nA jump to 2NT would be descriptive, but your first goal is to seek a Major suit fit. When you have two 4-card Majors you should respond "up-the-line" so you bid 1!H. Partner says 2!H. What do you bid now? [BID 4!H]\nPartner would not support your !H suit without 4 cards so you have an 8-card Major fit. There is no point in bidding !Ss.\nPartner has at least 13 points and you have 13 so you bid the game.\nSouth plays 4!H. West leads the !DT.\nMake a Plan, then click NEXT. [NEXT]\nTo make a PLAN for a suit contract you should count your losers.\nLosers: !S 0 : !H 1 : !D 0 : !C 3 : Total = 4\nThere is nothing you can do about losing the Ace of trumps. The three !C losers would only happen if West has the !CA and East wins a trick early, (say with the !HA), and leads a !C through your !CK.\nYou can take care of this possibility by discarding a !C from dummy BEFORE you play trumps. So win the !DK, and play !SA, !SK, !SQ, discarding dummy's !C3 on the last one. Then pull trumps. You will end up losing two !Cs and the !HA.\nClick NEXT to see the Deal that could have set you. [NEXT]\nEast would win his !HA and would switch to a black suit to lead up to dummy's weakness. In this case he would surely lead the !CQ, and you would lose three !C tricks and be down before you started.\nMaking a PLAN is a necessary part of being a good Declarer and Visualizing what might happen is a necessary part of making a Plan.
A4: 100Deals | B4: deal003.html | C4: 3 | D4: BID+NEXT | E4: S:AQ5 H:74 D:Q962 C:AJT8 | F4: S:KT H:QJT982 D:83 C:652 | G4: S:872 H:K6 D:AKJ4 C:KQ74 | H4: S:J9643 H:A53 D:T75 C:93 | I4: East | J4: pass 1NT | pass 3NT pass pass | pass | K4: 3NT | L4: South | M4: S4 | N4: You are South and it is your bid. Decide what you would say, then click on BID. [BID 1NT]\nWith 16 points and a balanced hand you should open 1NT. Do not worry about the lack of a !S stopper, a 1NT opening does not guarantee stoppers in all four suits.\nPartner raises you to 3NT.\nSouth plays 3NT. West leads the !S4.\nMake a Plan, then click NEXT. [NEXT]\nWinners: !S 1 : !H 0 : !D 4 : !C 4 : Total = 9\nIt's nice to have a hand where the Winner count is 9. And guess what? West probably has the !SK, so you can finesse on the first trick for an overtrick.\nHOLD IT! JUST STEP AWAY FROM THE QUEEN OF SPADES AND NOBODY WILL GET HURT.\nWhat if you tried the finesse and East had the !SK? And what if he then switched to the !HQ? And what if your opponents then took the next 6 !H tricks? \nI think you get the idea. Win the !SA immediately and then take your other 8 tricks.\nClick NEXT to see the complete Deal. [NEXT]\nThis wasn't one of those times.
A5: 100Deals | B5: deal004.html | C5: 4 | D5: BID+NEXT | E5: S:KQJ H:A862 D:Q63 C:T94 | F5: S:72 H:QT43 D:AJ92 C:Q73 | G5: S:T98653 H:K7 D:84 C:AKJ | H5: S:A4 H:J95 D:KT75 C:8652 | I5: South | J5: 1S | pass 2H pass 2S | pass 4S pass pass | pass | K5: 4S | L5: South | M5: D5 | N5: You are South and it is your bid. Decide what you would say, then click on BID. [BID 1!S]\nDon't think of passing. With 11 HCP and 2 length points you open 1!S. Partner responds 2!H. What is your next bid? [BID 2!S]\nYou must bid and you want to show that you have a bare minimum. You don't want to say 2NT because of that doubleton nothing !D. So you rebid your 6-card !S suit. Partner bids 4!S and everybody passes.\nSouth plays 4!S. West leads the !D5 on which you play dummy's !D3. East wins !DJ, plays !DA, then !D2.\nMake a Plan, then click NEXT. [NEXT]\nLosers: !S 1 : !H 0 : !D 2 : !C 1 : Total = 4\nYou have already lost the 2 !Ds and you sure can't escape losing the Ace of trumps. So you mustnot lose a !C trick. So your Plan will be to pull trumps, then finesse East for the !CQ. \nYou ruff the third !D, play !Ss until the !SA appears. When you regain the lead you pull any outstanding trumps, play one high !C, (in case someone has a singleton !CQ), then enter dummy with the !HA and make the !C finesse. Half of the time you make the contract, the other half you don't.\nClick NEXT to see the full deal. [NEXT]\nIt's never great when the success of your contract depends on a finesse, but sometimes that's your only hope - a 50% chance.
A6: 100Deals | B6: deal005.html | C6: 5 | D6: BID+NEXT | E6: S:J64 H:Q7 D:A983 C:KQ76 | F6: S:A7 H:K653 D:762 C:T543 | G6: S:KQT3 H:A4 D:QJT5 C:AJ2 | H6: S:9852 H:JT982 D:K4 C:98 | I6: East | J6: pass 1NT | pass 3NT pass pass | pass | K6: 3NT | L6: South | M6: HJ | N6: You are South and it is your bid. Decide what you would say, then click on BID. [BID 1NT]\nYou have a very solid 17 points and a balanced hand. You open 1NT. Partner responds 3NT and you pass.\nSouth plays 3NT. West leads the !HJ. You hopefully put on the !HQ, but East plays the !HK.\nMake a Plan, then click NEXT. [NEXT]\nYou hopefully put on the !HQ, but East plays the !HK.\nWinners: !S 0 : !H 1 : !D 1 : !C 4 : Total = 6\nA hold-up won't help unless East had a doubleton !H, giving West a 7-card suit. So you win your !HA. The !S suit is solid after the !SA is played, but before you could enjoy those 3 tricks the defenders would have really enjoyed a bunch of !Hs.\nYour only hope is to win 8 more tricks before you lose the lead. That means the !D finesse had better work. At trick 2 you lead your !DQ, playing low from dummy if West doesn't cover. Repeat the finesse as necessary. When West has the !DK you will make your contract, and when East has the !DK you will go down. That's a 50% chance, just like most finesses. But remember, if you had tried to establish the !S suit instead of taking the finesse your chance of making 3NT would be 0%.\nClick for the full deal. [NEXT]\n
A7: 100Deals | B7: deal006.html | C7: 6 | D7: BID+NEXT+ROTATE | E7: S:QJT9 H:A5 D:7542 C:973 | F7: S:K63 H:QJT83 D:J C:KJ62 | G7: S:A2 H:K742 D:A863 C:AT5 | H7: S:8754 H:96 D:KQT9 C:Q84 | I7: North | J7: 1NT | pass pass pass | | K7: 1NT | L7: North | M7: HQ | N7: You are South and it is your bid. Decide what you would say, then click on BID. [BID pass]\nYou have 7 points so you know your side does not have a game. You also have no reason to think there is any better contract than 1NT. So you pass.\nNorth would play 1NT. To make life more convenient the hands will be rotated so that South becomes declarer. \nClick ROTATE. [ROTATE]\nSouth plays 1NT. West leads the !HQ.\nMake a Plan, then click NEXT. [NEXT]\nWinners: !S 1 : !H 2 : !D 1 : !C 1 : Total = 5\nYou need two more winners. Even if the !Ds split 3-2 you can get only one more from that suit. So clearly you must use the !S suit. Since you have only one entry to dummy you must save it until the right time.\nWin the first trick with the !HK. Then play !SA followed by !S2. Continue playing !Ss until the !SK is forced out. Win whatever they play next and play your other winners. You cannot be stopped from taking 7 tricks.\nClick NEXT to see the full deal. [NEXT]\nWhat would you try next? A !S finesse? Whether West took his !SK right then or later you would go down. You could never reach dummy again.
A8: 100Deals | B8: deal007.html | C8: 7 | D8: BID+NEXT | E8: S:T64 H:KJ7 D:86 C:J7532 | F8: S:982 H:5 D:QT742 C:AK96 | G8: S:QJ5 H:AQT963 D:AK5 C:Q | H8: S:AK73 H:842 D:J93 C:T84 | I8: South | J8: 1H | pass 2H pass 4H | pass pass pass | | K8: 4H | L8: South | M8: SA | N8: You are South and it is your bid. Decide what you would say, then click on BID. [BID 4!H]\nYou have a nice hand, but 20 points is not strong enough to open 2!C. \nSo you open 1!H. Partner raises to 2!H. What do you bid now? [BID pass]\nPartner's raise to 2!H shows 6-10 points. You figure that should be enough for game but even if he has the full T you are not in slam range. So you bid the game. \nSouth plays 4!H. West leads !SA, then switches to !H2.\nMake a Plan, then click NEXT. [NEXT]\nLosers: !S 2 : !H 0 : !D 1 : !C 1 : Total = 4\nIt's a good thing you stopped at game - partner's hand is about as bad as it could be.\nThe PLAN turns out simple. You can't avoid either of the three black losers so you must eliminate the !D loser. You can ruff it in dummy. Just to be safe you pull one more round of trumps, then play !DA, !DK and !D5, ruffing in dummy. You will eventually get to your hand (with a !S or a !C ruff) and pull the last trump.\nClick NEXT to see the full deal. [NEXT]\nOnly a real beginner would have pulled all the trumps and not been able to ruff that !D.
A9: 100Deals | B9: deal008.html | C9: 8 | D9: BID+NEXT+ROTATE | E9: S:74 H:K53 D:AK962 C:KQ3 | F9: S:QJT82 H:T86 D:754 C:A5 | G9: S:A9 H:AJ2 D:QJ3 C:JT862 | H9: S:K653 H:Q974 D:T8 C:974 | I9: West | J9: pass 1C | pass 1D pass 1NT | pass 3NT pass pass | pass | K9: 3NT | L9: North | M9: SQ | N9: You are South and it is your bid. Decide what you would say, then click on BID. [BID pass]\nWith 16 points as Responder you are not quite strong enough for a jump-shift to 2 !D. That requires at least 17 points. A jump to 3NT fits the point range (16-18) but promises a stopper in all unbid suits. So instead you bid 1!D, knowing partner is forced to keep the bidding alive. He now replies 1NT. What is your next bid? [BID pass]\nUntil now you were thinking the hand might end up in a slam. Now, with partner's minimum rebid, you happily say 3NT which partner passes.\nNorth would play 3NT. \nClick [ROTATE]\nSouth plays 3NT. West leads the !SQ. East puts on the !SK.\nMake a Plan, then click NEXT. [NEXT]\nWinners: !S 1 : !H 2 : !D 5 : !C 0 : Total = 8\nLet's say you hold up on the first !S, hoping they switch suits. HA! They aren't about to switch suits and they drive out your !SA at trick 2. That actually clears the situation up and makes this plan pretty simple to make.\nYou have taken 1 !S, and you will surely make 5 !Ds. Despite the solidity of those !Cs you dare not try to win a !C trick, because the defenders will pounce on that first !C and then win a bunch of !S tricks. \nSo that makes it clear that you need 3 !H tricks, and there's only one way to get them. After taking your five !D tricks, play a !H to the !HK, then a !H back, finessing the !HJ. Half of the time you will make this contract, the other half of the time they will bury you with !Ss.\nClick NEXT to see the full deal. [NEXT]\n
A10: 100Deals | B10: deal009.html | C10: 9 | D10: BID+NEXT+ROTATE | E10: S:952 H:KQ92 D:KQ83 C:J7 | F10: S:KQJ8 H: D:9764 C:QT652 | G10: S:T63 H:AT754 D:AJ2 C:AK | H10: S:A74 H:J863 D:T5 C:9843 | I10: North | J10: 1H | pass 3H pass 4H | pass pass pass | K10: 4H | L10: North | N10: You are South and it is your bid. Decide what you would say, then click on BID. [BID 3!H]\nYou have 12 points which isn't quite enough to force to game.\nIt is just right for a limit raise though, so you bid 3!H.\nPartner does bid the game.\nNorth would play 4!H.\nClick [ROTATE]\nSouth plays 4!H. The defense takes the first three !S tricks, then switches to a !C.\nMake a Plan, then click NEXT. [NEXT]\nLosers: !S 3 : !H ?? : !D 0 : !C 0 : Total = 3+??\nWith no more outside losers your task is very very simple:DO NOT LOSE A TRUMP TRICK.\nThere is no problem if trumps split 2-2 or 3-1, so you can put your mind to 4-0 splits only. If West holds !H J 8 6 3 then it won't matter whether your first trump play is !HA or !HK, you will still be able to finesse the !HJ. But if East holds !H J 8 6 3 it is vital that you first play either the !HK or !HQ. If you start with the !HA you will have lost your finesse position. The general rule is to first play a high trump from the hand that has two. That preserves a finesse through either defender's !H J x x x.\nClick NEXT to see the full deal. [NEXT]\nNext visualize the situation if your first play was the !HK. West would show out and you would play the !HQ, then a small !H finessing your !HT. \nFinally visualize the situation if your first play was the !HK and it was East who showed out. You would play a small !H to your !HA, then lead a !H toward dummy finessing with the !H9.\nUsing the correct Plan guarantees the contract however !Hs split.
A11: 100Deals | B11: deal010.html | C11: 10 | D11: BID+NEXT | E11: S:KQ92 H:952 D:K7 C:KQ83 | F11: S: H:A874 D:QJ632 C:T764 | G11: S:A8754 H:T63 D:A8 C:AJ2 | H11: S:JT63 H:KQJ D:T954 C:95 | I11: North | J11: 1C pass 1S | pass 2S pass 4S | pass pass pass | K11: 4S | L11: South | N11: You are South and it is your bid. Decide what you would say, then click on BID. [BID 1!S]\nPartner has opened and you have 14 points. You know you belong in game but there is no need to jump and use up bidding space. You respond 1!S.\nPartner now bids 2!S. What do you bid next? [BID 4!S]\nYou know you should be in game and now you know the suit. You bid 4!S.\nSouth plays 4!S. The defense quickly takes three !H tricks, then switches to a !D.\nMake a Plan, then click NEXT. [NEXT]\nLosers: !S 0? : !H 3 : !D 0 : !C 0 : Total = 3?\nThis Deal is VERY similar to Deal 9 in that you are only worried about a 4-0 trump split. The reason that it shows up right here is to point out the difference between J 8 6 3 and J T 6 3.\nIf East holds !S J T 6 3 then there is nothing you can do about it - you will go down. If you lead a !S from dummy he will "split his honors" by playing the !ST. This will force your !SA and he can just sit back and wait for his !SJ to make a trick.\nBut if it is West with !S J T 6 3 you can keep him from winning a !S trick, IF YOUR FIRST !S PLAY IS THE !SA. East shows out and you play a small !S toward dummy's !S K Q 9. If West plays low you insert the !S9, if he plays one of his honors you win it, then return to your hand and finesse him out of the other honor.\nClick NEXT to see the full deal. [NEXT]\nIf your first !S was !SK or !SQ then it would be too late.\nClick NEXT to see an alternate deal. [NEXT]\nTo summarize: If you are missing J x x x your first play should be from the hand with two honors. Then you will be able to finesse in either direction. If you are missing J T x x your first play should be honor from the hand with only one. This will leave you with a double-finesse position in one direction. If the other defender has the trumps there is nothing you can do.
A12: 100Deals | B12: deal011.html | C12: 11 | D12: BID+NEXT | E12: S:K82 H:754 D:K9542 C:Q3 | F12: S:JT97 H:KQT6 D:J6 C:J54 | G12: S:A63 H:A92 D:A87 C:A976 | H12: S:Q54 H:J83 D:QT3 C:KT82 | I12: East | J12: pass 1NT | pass 2NT pass 3NT | pass pass pass | | K12: 3NT | L12: South | M12: C2 | N12: You are South and it is your bid. Decide what you would say, then click on BID. [BID 1NT]\nAces and Spaces is the description you often hear about this hand. But the REAL description is 16 points, balanced. So you open 1NT. Partner replies 2NT. What do you bid now? [BID 3NT]\nPartner is INVITING you to bid 3NT. If you have 17 points you should bid 3NT. If you have 15 points you should pass.\nWith 16 points you must make a judgement. This one is actually easy, despite the negative sound of "Aces and Spaces". In strength terms Aces are undervalued. Instead of being worth 4 points they are actually worth about 4.3 points. So you really do have a 17 point hand, and you bid 3NT.\nSouth plays 3NT. West leads the !C2.\nMake a Plan, then click NEXT. [NEXT]\nWinner count: !S 2 : !H 1 : !D 2 : !C 1 : Total = 6\nWow. Things do look a little Acey/Spacey. If the !Ds are 3-2, which is likely, you can establish 2 tricks there. You need one more and the best hope is the !CQ. There is a very good chance that West led from the !CK. So with a brief prayer to Brigidda (the Goddess of Bridge) you put up the !CQ. It wins the trick.\nNow you are on cruise-control. Play a !D to the !DA. Play another !D back to dummy's !DK (both defenders follow). Now a third !D sets up the rest of the suit.\nClick NEXT to see the full deal. [NEXT]\n
A13: 100Deals | B13: deal012.html | C13: 12 | D13: BID+NEXT+ROTATE | E13: S:85 H:J762 D:83 C:AKQ43 | F13: S:QT43 H:54 D:JT964 C:95 | G13: S:AK72 H:A83 D:AQ72 C:62 | H13: S:J96 H:KQT9 D:K5 C:JT87 | I13: North | J13: 1NT | pass 2C pass 2S | pass 3NT pass pass | pass | K13: 3NT | L13: North | M13: DJ | N13: You are South and it is your bid. Decide what you would say, then click on BID. [BID 2!C]\nDespite the great !C suit, you have a 4-card Major. It is your duty to first seek an 8-card Major fit, so you bid 2!C (Stayman). Partner replies 2!S. What do you bid? [BID 3NT]\nWell, that wasn't the Major suit you were hoping for.\nBut with 11 points you have enough for game, so you bid 3NT.\nNorth would play 3NT.\nClick [ROTATE]\nSouth plays 3NT. West leads !DJ, East plays !DK.\nMake a Plan, then click NEXT. [NEXT]\nWinners: !S 2 : !H 1 : !D 2 : !C 3 : Total = 8\nThanks to the opening lead you get an extra !D winner. Well, since the finesse would have worked it really isn't extra, it's just nice to know about it early. You need to find one more winner and the !C suit beckons. A 3-3 split would be very nice, but a 4-2 is more likely. Even with a 4-2 split you can still make your fifth !C good - but you must be careful with entries.\nSince you have no immediate problem in any suit you can afford to give up the lead. So you play the !C2 from your hand and the !C3 from dummy. In other words, you duck a !C. Somebody will win this trick cheaply and no doubt play another !D. You don't mind at all - you win the !DQ, the !S A K, the !HA and dummy's !C A K Q 4, all of which are good.\nClick NEXT to see the full deal. [NEXT]\nIf you played a high !C first you would never have an entry back to dummy. You would have been forced to try to get there with the !HJ but as you can see, that wouldn't work.\nIf you had just played the !Cs from the top you would have made an overtrick when they split 3-3, but gone down when they split 4-2. Making an overtrick about 40% of the time is a high price to pay for going down the other 60%.
A14: 100Deals | B14: deal013.html | C14: 13 | D14: BID+NEXT+ROTATE | E14: S: H:T965 D:AT9643 C:Q72 | F14: S:Q986 H:KQJ3 D:KQ C:853 | G14: S:AJT7542 H: D:75 C:AKJT | H14: S:K3 H:A8742 D:J82 C:964 | I14: North | J14: 1S | pass 1NT pass 4S | pass pass pass | K14: 4S | L14: North | M14: HK | N14: You are South and it is your bid. Decide what you would say, then click on BID. [BID 1NT]\nThis is awkward. With 8 points you must respond, but you cannot bid a new suit at the 2-level without 11 or more. Although you are far from balanced you must say 1NT.\nYou might as well not have worried. Partner jumps to 4!S and you pass.\nNorth would play 4!S.\nClick [ROTATE]\nSouth plays 4!S. West leads the !HK.\nMake a Plan, then click NEXT. [NEXT]\nLosers: !S ? : !H 0 : !D 1 : !C 0 : Total = ?\nThat 1 !D loser is definite. So instead of guessing how many !S losers you have, just approach it from the viewpoint that you can afford 2 but not 3.\nIf the missing !Ss split 3-3 then your life is easy. You play !SA, then any !S. Win their return and play any !S. The defense can win two !Ss but no more.\nIt's when the !Ss are splitting 4-2 that you must be careful. If somebody has !S K Q 9 3 for example you will go down. The one important distribution to guard against is a doubleton honor in one hand. In this case your second !S play must be a LOW !S. When this drives out one honor your !S J T can insure that only one more trick is lost.\nClick NEXT to see the full deal. [NEXT]\nBut if your second !S play is a small !S East will win the !SK and you will be left with the !S J T to deal with West's !S Q 9, holding him to just one more trick.
A15: 100Deals | B15: deal014.html | C15: 14 | D15: BID+NEXT+ROTATE | E15: S:A74 H:KT953 D:J53 C:Q3 | F15: S:JT92 H:862 D:87 C:J975 | G15: S:K63 H:QJ D:AK42 C:AT64 | H15: S:Q85 H:A74 D:QT96 C:K82 | I15: North | J15: 1NT | pass 3H pass 3NT | pass pass pass | K15: 3NT | L15: North | M15: SJ | N15: You are South and it is your bid. Decide what you would say, then click on BID.\n<i>You and partner do NOT play Jacoby Transfer Bids</i>. [BID 3!H]\nWith 11 points you know you want to reach game since partner has at least 15. However, you aren't sure at this point just which game to reach. If you knew partner held 3!Hs you'd choose 4!H since you would have an 8-card Major fit. On the other hand, if you knew partner had only a doubleton !H you would choose 3NT, which would probably be better. So you jump to 3!H. This bid tells partner to "Pick a Game". \nHe picks 3NT.\nNorth would play 3NT.\nClick [ROTATE]\nSouth plays 3NT. West leads the !SJ.\nMake a Plan, then click NEXT. [NEXT]\nWinner count: !S 2 : !H 0 : !D 2 : !C 1 : Total = 5\nAlthough the !D and !C suits offer the possibility for creating a winner it is evident that you really need to bring in the !Hs. By driving out the !HA you will establish the 4 winners that you need. The problem is that when you play !HQ then !HJ a good defender will hold up his !HA. You could get to dummy with the !SA and continue !Hs, but you would no longer have a sure entry to get back to those winners.\nThere is an almost foolproof plan. Win the first trick with your !SK (saving dummy's !SA). Lead !HQ, then !HJ, OVERTAKING WITH DUMMY'S !HK. Now continue the !HT driving out the !HA. You will be able to reach the !H tricks with the !SA.\nClick NEXT to see the full deal. [NEXT]\n
